Workbook
Name lstRegion: Lists!$A$1:$A$5
Name lstChannel: Lists!$B$1:$B$4
Name lstCategory: Lists!$C$1:$C$5
Name lstYesNo: Lists!$D$1:$D$2
Name pLateDays: Parameters!$C$5
Name pLowMargin: Parameters!$C$6
Name pHighCutoff: Parameters!$C$8
Name pRegion: Dashboard!$C$5
Name pChannel: Dashboard!$E$5
Name pCategory: Dashboard!$G$5
Name pIncludeCancelled: Dashboard!$I$5
Name pStart: Dashboard!$K$5
Name pEnd: Dashboard!$M$5

Sheet Cover
A1: Harbor & Co. advanced data analysis
A2: Excel pipeline · extract, clean, analyze, dashboard, test
B4: Objective
B5: Turn a dirty order extract into a decision-ready sales view: what sold, where, through which channel, and which orders are late, returned, or thin on margin.
B8: Pipeline
B9: 1. Raw_Data holds the dirty extract. 2. pipeline/clean.py standardizes aliases, dates, numbers, duplicates, and invalid rows. 3. Cleaned_Data stores the surviving orders. Revenue, margin, and flags are Excel formulas. 4. Chart_Data and Dashboard aggregate with SUMIFS / COUNTIFS / AVERAGEIFS so filters recalculate in Excel. 5. QA_Tests checks those formulas against the values locked by the Python run.
B13: Default window
B14: 2024-01-01 to 2025-09-30. Cancelled orders are excluded from sales KPIs. Seed 42. Raw rows 1,649. Clean rows 1,618.
B16: Headline result
B17: Net revenue $2,220,660 · Orders 1,558 · AOV $1,425 · Gross margin 29.4% · Return rate 7.1% · On time 75.5%.
B19: How to use the dashboard
B20: Open Dashboard. Pick Region, Channel, Category, the cancelled switch, and the date window. Excel recalculates the KPI cards and all ten charts. Comparison charts keep their breakdown: the region chart does not collapse when you pick one region.

Sheet Lists
A1: All | B1: All | C1: All | D1: Yes
A2: North | B2: Store | C2: Furniture | D2: No
A3: South | B3: Online | C3: Lighting
A4: East | B4: Wholesale | C4: Textiles
A5: West | C5: Kitchen

Sheet Parameters
A1: Model parameters
A2: Dashboard dropdowns are the filters. Thresholds below drive late-shipment and margin flags.
B4: Parameter | C4: Value | D4: What it controls | E4: Limitation
B5: Late shipment threshold (days) | C5: 7 | D5: LateFlag and the on-time KPI. Edit this cell and Excel recalculates. | E5: Does not rewrite history; it only changes the cutoff.
B6: Low-margin threshold | C6: 0.15 | D6: Low-margin KPI. Stored as a fraction (0.15 = 15%). | E6: Compared with each order's margin, not the weighted regional margin.
B7: High-value percentile | C7: 0.9 | D7: Documented percentile used when the pipeline computed the cutoff. | E7: Changing this cell does not recompute the cutoff. Rerun the pipeline.
B8: High-value cutoff | C8: 3064.63 | D8: HighValueFlag. Orders at or above this net revenue count as high value. | E8: Cutoff is fixed for the saved parameter set and the All/All/All filter. Dropdowns do not rebuild the percentile.
B9: Random seed | C9: 42 | D9: Makes the synthetic extract reproducible. | E9: The extract is synthetic. It is not a client ledger.
B10: Include cancelled (echo) | C10: =pIncludeCancelled | D10: Mirrors the dashboard switch. | E10: Yes includes cancelled orders in sales KPIs. Return rate and on-time still exclude them.
B11: Analysis start (echo) | C11: =pStart | D11: Mirrors the dashboard date. | E11: Rows outside the window stay on Cleaned_Data and drop out of every SUMIFS.
B12: Analysis end (echo) | C12: =pEnd | D12: Mirrors the dashboard date. | E12: Same window rule as the start date.

Sheet Raw_Data
A1: OrderID | B1: OrderDate | C1: Region | D1: Channel | E1: Category | F1: Product | G1: Segment | H1: Quantity | I1: UnitPrice | J1: Discount | K1: UnitCost | L1: ShipDays | M1: Status | N1: SalesRep
A2: HC-100000 | B2: 05/21/2025 | C2: West | D2: Online | E2: Furniture | F2: Linen Sofa | G2: Consumer | H2: 2 | I2: $1,307.21 | J2: 0.14 | K2: 862.76 | L2: 4 | M2: Completed | N2: J. Patel
A3: HC-100001 | B3: 03-Sep-24 | C3: West | D3: Online | E3: Furniture | F3: Lounge Chair | G3: Home Office | H3: 2 | I3: 453.45 | J3: 0.03 | K3: 272.07 | L3: 10 | M3: Completed | N3: R. Ibarra
A4: HC-100002 | B4: 2025/03/04 | C4: West | D4: Online | E4: Lighting | F4: Arc Lamp | G4: Corporate | H4: 3 | I4: 292.13 | J4: 0.13 | K4: 140.22 | L4: 6 | M4: Completed | N4: L. Berger
A5: HC-100003 | B5: 18.05.2025 | C5: Eas | D5: Online | E5: FURNITURE | F5: Walnut Shelf | G5: Consumer | H5: 2 | I5: 188.96 | J5: 0.09 | K5: 103.93 | L5: 6 | M5: Completed | N5: A. Shah
A6: HC-100004 | B6: 03/09/2024 | C6: West | D6: web | E6: Furniture | F6: Lounge Chair | G6: Consumer | H6: 2 | I6: 495.08 | J6: 0.04 | K6: 297.05 | L6: 5 | M6: complete | N6: P. Rossi
A7: HC-100005 | B7: 30-Jul-24 | C7: North | D7: Wholesale | E7: Lighting | F7: Brass Sconce | G7: Corporate | H7: 13 | I7: 141.77 | J7: 18% | K7: 65.22 | L7: 3 | M7: Completed | N7: R. Ibarra
A8: HC-100006 | B8: 2024/04/22 | C8: North | D8: web | E8: Furniture | F8: Linen Sofa | G8: Home Office | H8: 3 | I8: 1219.37 | J8: 0.11 | K8: 804.79 | L8: 5 | M8: Completed | N8: R. Ibarra
A9: HC-100007 | B9: 09.10.2024 | C9: West | D9: B2B | E9: Furniture | F9: Oak Desk | H9: 16 | I9: 863.15 | J9: 0.14 | K9: 535.15 | L9: 6 | M9: Completed | N9: S. Nguyen
A10: HC-100008 | B10: 08/29/2024 | C10: West | D10: Store | E10: Lighting | F10: Brass Sconce | G10: Home Office | H10: 2 | I10: 132.49 | J10: 0.11 | K10: 60.94 | L10: 3 | M10: Completed | N10: M. Okonkwo
A11: HC-100009 | B11: 28-Jul-24 | C11: West | D11: Store | E11: Furniture | F11: Oak Desk | H11: 4 | I11: 796.89 | J11: 0.02 | K11: 494.07 | L11: 3 | M11: COMPLETED | N11: J. Patel
A12: HC-100010 | B12: 2025/03/24 | C12: North | D12: Online | E12: Textiles | F12: Cotton Duvet | G12: Consumer | H12: one | I12: 112.78 | J12: 0.04 | K12: 49.62 | L12: 5 | M12: Returned | N12: P. Rossi
A13: HC-100011 | B13: 05.09.2025 | C13: West | D13: Online | E13: Lighting | F13: Pendant Light | G13: Consumer | H13: 2 | I13: 168.74 | J13: 0.02 | K13: 84.37 | L13: 4 | M13: Completed | N13: K. Mensah
A14: HC-100012 | B14: 06/09/2024 | C14: West | D14: Online | E14: Furniture | F14: Oak Desk | G14: consumer | H14: 3 | I14: 792.45 | J14: 12% | K14: 491.32 | L14: 4 | M14: complete | N14: A. Shah
A15: HC-100013 | B15: 25-Sep-24 | C15: South | D15: Wholesale | E15: Kitchen | F15: Ceramic Set | G15: consumer | H15: 23 | I15: 82.38 | J15: 0.16 | K15: 31.30 | L15: 9 | M15: complete | N15: A. Shah
A16: HC-100014 | B16: 2025/09/10 | C16: West | D16: Online | E16: Textiles | F16: Linen Curtain | G16: Consumer | H16: 3 | I16: 95.22 | J16: 0.11 | K16: 42.85 | L16: 1 | M16: RETURNED | N16: M. Okonkwo
A17: HC-100015 | B17: 15.07.2024 | C17: WEST | D17: Wholesale | E17: Lighting | F17: Brass Sconce | G17: Consumer | H17: 17 | I17: 147.81 | J17: 0.23 | K17: 67.99 | L17: 7 | M17: Completed | N17: K. Mensah
A18: HC-100016 | B18: 03/17/2024 | C18: north | D18: B2B | E18: Kitchen | F18: Cast Skillet | G18: Consumer | H18: 19 | I18: 56.55 | J18: 0.28 | K18: 22.62 | L18: 6 | M18: Returned | N18: S. Nguyen
A19: HC-100017 | B19: 05-Dec-24 | C19: North | D19: Store | E19: Furniture | F19: Lounge Chair | G19: Home Office | H19: 3 | I19: 501.07 | J19: 0.05 | K19: 300.64 | L19: 8 | M19: Completed | N19: P. Rossi
A20: HC-100018 | B20: 2024/12/30 | C20: west | D20: Online | E20: Lighting | F20: Brass Sconce | G20: Corporate | H20: 3 | I20: 150.11 | J20: 0.13 | K20: 69.05 | L20: 10 | M20: Compleated | N20: J. Patel
A21: HC-100019 | B21: 17.05.2025 | C21: West | D21: Wholesale | E21: FURNITURE | F21: Oak Desk | G21: Consumer | H21: 29 | I21: 907.08 | J21: 0.14 | K21: 562.39 | L21: 6 | M21: Completed | N21: K. Mensah
A22: HC-100020 | B22: 02/24/2024 | C22: west | D22: Store | E22: Kitchen | F22: Chef Knife | G22: Corporate | H22: 1 | I22: 68.38 | J22: 0.10 | K22: 24.62 | L22: 8 | M22: Completed | N22: A. Shah
A23: HC-100021 | B23: 17-Mar-25 | C23: East | D23: Store | E23: Textiles | F23: Linen Curtain | G23: Consumer | H23: 1 | I23: 88.37 | J23: 0.11 | K23: 39.77 | L23: 7 | M23: Completed | N23: A. Shah
... A31: HC-100029 | B31: 05-Sep-25 | C31: West | D31: Online | E31: Lighting | F31: Arc Lamp | G31: Consumer | H31: 1 | I31: 323.76 | J31: 0.03 | K31: 155.40 | L31: 7 | M31: Completed | N31: A. Shah
A32: HC-100030 | B32: 2024/02/11 | C32: East | D32: e-commerce | E32: Textiles | F32: Wool Throw | H32: 1 | I32: 70.75 | J32: 0.14 | K32: 29.71 | L32: 7 | M32: Completed | N32: K. Mensah
A33: HC-100031 | B33: 16.08.2024 | C33: West | D33: Store | E33: Textiles | F33: Cotton Duvet | G33: Consumer | H33: 2 | I33: 127.42 | J33: 0.03 | K33: 56.07 | L33: 7 | M33: Completed | N33: R. Ibarra
A34: HC-100032 | B34: 08/23/2025 | C34: South | D34: Store | E34: Lighting | F34: Arc Lamp | G34: Consumer | H34: 1 | I34: 286.08 | J34: 0.02 | K34: 137.32 | L34: 6 | M34: Completed | N34: R. Ibarra
A35: HC-100033 | B35: 14-Dec-24 | C35: East | D35: Store | E35: Furniture | F35: Linen Sofa | G35: Corporate | H35: 3 | I35: 1192.38 | J35: 0.02 | K35: 786.97 | L35: 9 | M35: Completed | N35: S. Nguyen
A36: HC-100034 | B36: 2025/02/22 | C36: West | D36: Online | E36: Lighting | F36: Arc Lamp | G36: Consumer | H36: 1 | I36: 290.31 | J36: 0.17 | K36: 139.35 | L36: 1 | M36: complete | N36: J. Patel
A37: HC-100035 | B37: 05.10.2024 | C37: NORTH | D37: Wholesale | E37: Furniture | F37: Oak Desk | G37: Corporate | H37: 11 | I37: 817.57 | J37: 22% | K37: 506.89 | L37: 5 | M37: Completed | N37: S. Nguyen
A38: HC-100036 | B38: 04/10/2024 | C38: North | D38: Store | E38: Kitchen | F38: Ceramic Set | G38: Consumer | H38: 1 | I38: 79.55 | J38: 0.02 | K38: 30.23 | L38: 1 | M38: Compleated | N38: A. Shah
A39: HC-100037 | B39: 30-Nov-24 | C39: west | D39: Store | E39: Kitchen | F39: Chef Knife | G39: Consumer | H39: 2 | I39: 65.03 | J39: 0.10 | K39: 23.41 | L39: 7 | M39: Completed | N39: L. Berger
A40: HC-100038 | B40: 2024/04/24 | C40: East | D40: Store | E40: Lighting | F40: Arc Lamp | G40: Consumer | H40: 1 | I40: 257.42 | J40: 0.00 | K40: 123.56 | L40: 10 | M40: Cancelled | N40: J. Patel
A41: HC-100039 | B41: 02.01.2024 | C41: North | D41: Wholesale | E41: FURNITURE | F41: Walnut Shelf | G41: consumer | H41: 25 | I41: 216.35 | J41: 0.23 | K41: 118.99 | L41: 8 | M41: Completed | N41: S. Nguyen
A42: HC-100040 | B42: 07/21/2025 | C42: East | D42: Store | E42: Kitchen | F42: Chef Knife | G42: Consumer | H42: 2 | I42: 60.91 | J42: 0.02 | K42: 21.93 | L42: 6 | M42: Completed | N42: M. Okonkwo
A43: HC-100041 | B43: 27-Jul-25 | C43: North | D43: Store | E43: Textiles | F43: Linen Curtain | G43: Consumer | H43: 2 | I43: 93.13 | J43: 0.12 | K43: 41.91 | L43: 5 | M43: Completed | N43: A. Shah
A44: HC-100042 | B44: 2024/04/10 | C44: east | D44: Store | E44: Kitchen | F44: Ceramic Set | G44: Consumer | H44: 3 | I44: 80.54 | J44: 0.01 | K44: 30.60 | L44: 7 | M44: Completed | N44: M. Okonkwo
... A55: HC-100053 | B55: 13-Feb-25 | C55: West | D55: In-Store | E55: Lighting | F55: Arc Lamp | G55: Home Office | H55: 3 | I55: $319.23 | J55: 0.06 | K55: 153.23 | L55: 4 | M55: Completed | N55: S. Nguyen
A56: HC-100054 | B56: 2025/06/22 | C56: West | D56: Store | E56: Furniture | F56: Oak Desk | H56: 3 | I56: 838.83 | J56: 10% | K56: 520.07 | L56: 6 | M56: Compleated | N56: J. Patel
A57: HC-100055 | B57: 02.05.2024 | C57: North | D57: Wholesale | E57: KITCHEN | F57: Chef Knife | G57: Consumer | H57: 23 | I57: 59.83 | J57: 0.28 | K57: 21.54 | L57: 8 | M57: Completed | N57: L. Berger
...

Sheet Lookup_Maps
A1: Alias maps
A2: The cleaning stage applies these maps. They are reproduced here so the workbook can be audited without opening the Python code.
B4: Alias | C4: Standard value
B5: north | C5: North
B6: nort | C6: North
B7: south | C7: South
B8: sout | C8: South
B9: east | C9: East
B10: eas | C10: East
B11: west | C11: West
B12: wes | C12: West
B14: Alias | C14: Standard value
B15: store | C15: Store
B16: retail | C16: Store
... B49: home-office | C49: Home Office

Sheet Cleaned_Data
A1: OrderID | B1: OrderDate | C1: Region | D1: Channel | E1: Category | F1: Product | G1: Segment | H1: Quantity | I1: UnitPrice | J1: Discount | K1: UnitCost | L1: ShipDays | M1: Status | N1: SalesRep | O1: QtyAdjusted | P1: GrossRevenue | Q1: NetRevenue | R1: TotalCost | S1: Margin | T1: Year | U1: Quarter | V1: YearMonth | W1: LateFlag | X1: HighValueFlag | Y1: ReturnFlag
A2: HC-100000 | B2: 45798 | C2: West | D2: Online | E2: Furniture | F2: Linen Sofa | G2: Consumer | H2: 2 | I2: 1307.21 | J2: 0.14 | K2: 862.76 | L2: 4 | M2: Completed | N2: J. Patel | O2: No | P2: =H2*I2 | Q2: =P2*(1-J2) | R2: =H2*K2 | S2: =IF(Q2=0,"",(Q2-R2)/Q2) | T2: =YEAR(B2) | U2: =YEAR(B2)&"-Q"&ROUNDUP(MONTH(B2)/3,0) | V2: =TEXT(B2,"YYYY-MM") | W2: =IF(L2="","",IF(L2>pLateDays,1,0)) | X2: =IF(Q2>=pHighCutoff,1,0) | Y2: =IF(M2="Returned",1,0)
A3: HC-100001 | B3: 45538 | C3: West | D3: Online | E3: Furniture | F3: Lounge Chair | G3: Home Office | H3: 2 | I3: 453.45 | J3: 0.03 | K3: 272.07 | L3: 10 | M3: Completed | N3: R. Ibarra | O3: No | P3: =H3*I3 | Q3: =P3*(1-J3) | R3: =H3*K3 | S3: =IF(Q3=0,"",(Q3-R3)/Q3) | T3: =YEAR(B3) | U3: =YEAR(B3)&"-Q"&ROUNDUP(MONTH(B3)/3,0) | V3: =TEXT(B3,"YYYY-MM") | W3: =IF(L3="","",IF(L3>pLateDays,1,0)) | X3: =IF(Q3>=pHighCutoff,1,0) | Y3: =IF(M3="Returned",1,0)
A4: HC-100002 | B4: 45720 | C4: West | D4: Online | E4: Lighting | F4: Arc Lamp | G4: Corporate | H4: 3 | I4: 292.13 | J4: 0.13 | K4: 140.22 | L4: 6 | M4: Completed | N4: L. Berger | O4: No | P4: =H4*I4 | Q4: =P4*(1-J4) | R4: =H4*K4 | S4: =IF(Q4=0,"",(Q4-R4)/Q4) | T4: =YEAR(B4) | U4: =YEAR(B4)&"-Q"&ROUNDUP(MONTH(B4)/3,0) | V4: =TEXT(B4,"YYYY-MM") | W4: =IF(L4="","",IF(L4>pLateDays,1,0)) | X4: =IF(Q4>=pHighCutoff,1,0) | Y4: =IF(M4="Returned",1,0)
A5: HC-100003 | B5: 45795 | C5: East | D5: Online | E5: Furniture | F5: Walnut Shelf | G5: Consumer | H5: 2 | I5: 188.96 | J5: 0.09 | K5: 103.93 | L5: 6 | M5: Completed | N5: A. Shah | O5: No | P5: =H5*I5 | Q5: =P5*(1-J5) | R5: =H5*K5 | S5: =IF(Q5=0,"",(Q5-R5)/Q5) | T5: =YEAR(B5) | U5: =YEAR(B5)&"-Q"&ROUNDUP(MONTH(B5)/3,0) | V5: =TEXT(B5,"YYYY-MM") | W5: =IF(L5="","",IF(L5>pLateDays,1,0)) | X5: =IF(Q5>=pHighCutoff,1,0) | Y5: =IF(M5="Returned",1,0)
A6: HC-100004 | B6: 45360 | C6: West | D6: Online | E6: Furniture | F6: Lounge Chair | G6: Consumer | H6: 2 | I6: 495.08 | J6: 0.04 | K6: 297.05 | L6: 5 | M6: Completed | N6: P. Rossi | O6: No | P6: =H6*I6 | Q6: =P6*(1-J6) | R6: =H6*K6 | S6: =IF(Q6=0,"",(Q6-R6)/Q6) | T6: =YEAR(B6) | U6: =YEAR(B6)&"-Q"&ROUNDUP(MONTH(B6)/3,0) | V6: =TEXT(B6,"YYYY-MM") | W6: =IF(L6="","",IF(L6>pLateDays,1,0)) | X6: =IF(Q6>=pHighCutoff,1,0) | Y6: =IF(M6="Returned",1,0)
A7: HC-100005 | B7: 45503 | C7: North | D7: Wholesale | E7: Lighting | F7: Brass Sconce | G7: Corporate | H7: 13 | I7: 141.77 | J7: 0.18 | K7: 65.22 | L7: 3 | M7: Completed | N7: R. Ibarra | O7: No | P7: =H7*I7 | Q7: =P7*(1-J7) | R7: =H7*K7 | S7: =IF(Q7=0,"",(Q7-R7)/Q7) | T7: =YEAR(B7) | U7: =YEAR(B7)&"-Q"&ROUNDUP(MONTH(B7)/3,0) | V7: =TEXT(B7,"YYYY-MM") | W7: =IF(L7="","",IF(L7>pLateDays,1,0)) | X7: =IF(Q7>=pHighCutoff,1,0) | Y7: =IF(M7="Returned",1,0)
A8: HC-100006 | B8: 45404 | C8: North | D8: Online | E8: Furniture | F8: Linen Sofa | G8: Home Office | H8: 3 | I8: 1219.37 | J8: 0.11 | K8: 804.79 | L8: 5 | M8: Completed | N8: R. Ibarra | O8: No | P8: =H8*I8 | Q8: =P8*(1-J8) | R8: =H8*K8 | S8: =IF(Q8=0,"",(Q8-R8)/Q8) | T8: =YEAR(B8) | U8: =YEAR(B8)&"-Q"&ROUNDUP(MONTH(B8)/3,0) | V8: =TEXT(B8,"YYYY-MM") | W8: =IF(L8="","",IF(L8>pLateDays,1,0)) | X8: =IF(Q8>=pHighCutoff,1,0) | Y8: =IF(M8="Returned",1,0)
A9: HC-100007 | B9: 45574 | C9: West | D9: Wholesale | E9: Furniture | F9: Oak Desk | G9: Unknown | H9: 16 | I9: 863.15 | J9: 0.14 | K9: 535.15 | L9: 6 | M9: Completed | N9: S. Nguyen | O9: No | P9: =H9*I9 | Q9: =P9*(1-J9) | R9: =H9*K9 | S9: =IF(Q9=0,"",(Q9-R9)/Q9) | T9: =YEAR(B9) | U9: =YEAR(B9)&"-Q"&ROUNDUP(MONTH(B9)/3,0) | V9: =TEXT(B9,"YYYY-MM") | W9: =IF(L9="","",IF(L9>pLateDays,1,0)) | X9: =IF(Q9>=pHighCutoff,1,0) | Y9: =IF(M9="Returned",1,0)
A10: HC-100008 | B10: 45533 | C10: West | D10: Store | E10: Lighting | F10: Brass Sconce | G10: Home Office | H10: 2 | I10: 132.49 | J10: 0.11 | K10: 60.94 | L10: 3 | M10: Completed | N10: M. Okonkwo | O10: No | P10: =H10*I10 | Q10: =P10*(1-J10) | R10: =H10*K10 | S10: =IF(Q10=0,"",(Q10-R10)/Q10) | T10: =YEAR(B10) | U10: =YEAR(B10)&"-Q"&ROUNDUP(MONTH(B10)/3,0) | V10: =TEXT(B10,"YYYY-MM") | W10: =IF(L10="","",IF(L10>pLateDays,1,0)) | X10: =IF(Q10>=pHighCutoff,1,0) | Y10: =IF(M10="Returned",1,0)
A11: HC-100009 | B11: 45501 | C11: West | D11: Store | E11: Furniture | F11: Oak Desk | G11: Unknown | H11: 4 | I11: 796.89 | J11: 0.02 | K11: 494.07 | L11: 3 | M11: Completed | N11: J. Patel | O11: No | P11: =H11*I11 | Q11: =P11*(1-J11) | R11: =H11*K11 | S11: =IF(Q11=0,"",(Q11-R11)/Q11) | T11: =YEAR(B11) | U11: =YEAR(B11)&"-Q"&ROUNDUP(MONTH(B11)/3,0) | V11: =TEXT(B11,"YYYY-MM") | W11: =IF(L11="","",IF(L11>pLateDays,1,0)) | X11: =IF(Q11>=pHighCutoff,1,0) | Y11: =IF(M11="Returned",1,0)
A12: HC-100010 | B12: 45740 | C12: North | D12: Online | E12: Textiles | F12: Cotton Duvet | G12: Consumer | H12: 1 | I12: 112.78 | J12: 0.04 | K12: 49.62 | L12: 5 | M12: Returned | N12: P. Rossi | O12: No | P12: =H12*I12 | Q12: =P12*(1-J12) | R12: =H12*K12 | S12: =IF(Q12=0,"",(Q12-R12)/Q12) | T12: =YEAR(B12) | U12: =YEAR(B12)&"-Q"&ROUNDUP(MONTH(B12)/3,0) | V12: =TEXT(B12,"YYYY-MM") | W12: =IF(L12="","",IF(L12>pLateDays,1,0)) | X12: =IF(Q12>=pHighCutoff,1,0) | Y12: =IF(M12="Returned",1,0)
A13: HC-100011 | B13: 45905 | C13: West | D13: Online | E13: Lighting | F13: Pendant Light | G13: Consumer | H13: 2 | I13: 168.74 | J13: 0.02 | K13: 84.37 | L13: 4 | M13: Completed | N13: K. Mensah | O13: No | P13: =H13*I13 | Q13: =P13*(1-J13) | R13: =H13*K13 | S13: =IF(Q13=0,"",(Q13-R13)/Q13) | T13: =YEAR(B13) | U13: =YEAR(B13)&"-Q"&ROUNDUP(MONTH(B13)/3,0) | V13: =TEXT(B13,"YYYY-MM") | W13: =IF(L13="","",IF(L13>pLateDays,1,0)) | X13: =IF(Q13>=pHighCutoff,1,0) | Y13: =IF(M13="Returned",1,0)
... A133: HC-100131 | B133: 45776 | C133: South | D133: Online | E133: Lighting | F133: Arc Lamp | G133: Consumer | H133: 1 | I133: 291 | J133: 0.04 | K133: 139.68 | L133: 6 | M133: Completed | N133: L. Berger | O133: No | P133: =H133*I133 | Q133: =P133*(1-J133) | R133: =H133*K133 | S133: =IF(Q133=0,"",(Q133-R133)/Q133) | T133: =YEAR(B133) | U133: =YEAR(B133)&"-Q"&ROUNDUP(MONTH(B133)/3,0) | V133: =TEXT(B133,"YYYY-MM") | W133: =IF(L133="","",IF(L133>pLateDays,1,0)) | X133: =IF(Q133>=pHighCutoff,1,0) | Y133: =IF(M133="Returned",1,0)
A134: HC-100132 | B134: 45633 | C134: East | D134: Store | E134: Textiles | F134: Linen Curtain | G134: Consumer | H134: 5 | I134: 85.4 | J134: 0.12 | K134: 38.43 | M134: Completed | N134: L. Berger | O134: No | P134: =H134*I134 | Q134: =P134*(1-J134) | R134: =H134*K134 | S134: =IF(Q134=0,"",(Q134-R134)/Q134) | T134: =YEAR(B134) | U134: =YEAR(B134)&"-Q"&ROUNDUP(MONTH(B134)/3,0) | V134: =TEXT(B134,"YYYY-MM") | W134: =IF(L134="","",IF(L134>pLateDays,1,0)) | X134: =IF(Q134>=pHighCutoff,1,0) | Y134: =IF(M134="Returned",1,0)
A135: HC-100133 | B135: 45497 | C135: South | D135: Wholesale | E135: Furniture | F135: Walnut Shelf | G135: Consumer | H135: 26 | I135: 236.05 | J135: 0.13 | K135: 129.83 | L135: 4 | M135: Cancelled | N135: P. Rossi | O135: No | P135: =H135*I135 | Q135: =P135*(1-J135) | R135: =H135*K135 | S135: =IF(Q135=0,"",(Q135-R135)/Q135) | T135: =YEAR(B135) | U135: =YEAR(B135)&"-Q"&ROUNDUP(MONTH(B135)/3,0) | V135: =TEXT(B135,"YYYY-MM") | W135: =IF(L135="","",IF(L135>pLateDays,1,0)) | X135: =IF(Q135>=pHighCutoff,1,0) | Y135: =IF(M135="Returned",1,0)
A136: HC-100134 | B136: 45499 | C136: South | D136: Store | E136: Textiles | F136: Cotton Duvet | G136: Consumer | H136: 2 | I136: 115.11 | J136: 0.05 | K136: 50.65 | L136: 7 | M136: Completed | N136: S. Nguyen | O136: No | P136: =H136*I136 | Q136: =P136*(1-J136) | R136: =H136*K136 | S136: =IF(Q136=0,"",(Q136-R136)/Q136) | T136: =YEAR(B136) | U136: =YEAR(B136)&"-Q"&ROUNDUP(MONTH(B136)/3,0) | V136: =TEXT(B136,"YYYY-MM") | W136: =IF(L136="","",IF(L136>pLateDays,1,0)) | X136: =IF(Q136>=pHighCutoff,1,0) | Y136: =IF(M136="Returned",1,0)
A137: HC-100135 | B137: 45749 | C137: South | D137: Store | E137: Textiles | F137: Wool Throw | G137: Unknown | H137: 2 | I137: 73.98 | J137: 0.01 | K137: 31.07 | L137: 7 | M137: Completed | N137: L. Berger | O137: No | P137: =H137*I137 | Q137: =P137*(1-J137) | R137: =H137*K137 | S137: =IF(Q137=0,"",(Q137-R137)/Q137) | T137: =YEAR(B137) | U137: =YEAR(B137)&"-Q"&ROUNDUP(MONTH(B137)/3,0) | V137: =TEXT(B137,"YYYY-MM") | W137: =IF(L137="","",IF(L137>pLateDays,1,0)) | X137: =IF(Q137>=pHighCutoff,1,0) | Y137: =IF(M137="Returned",1,0)
A138: HC-100136 | B138: 45643 | C138: North | D138: Store | E138: Textiles | F138: Wool Throw | G138: Consumer | H138: 3 | I138: 71.66 | J138: 0.07 | K138: 30.1 | L138: 7 | M138: Completed | N138: L. Berger | O138: No | P138: =H138*I138 | Q138: =P138*(1-J138) | R138: =H138*K138 | S138: =IF(Q138=0,"",(Q138-R138)/Q138) | T138: =YEAR(B138) | U138: =YEAR(B138)&"-Q"&ROUNDUP(MONTH(B138)/3,0) | V138: =TEXT(B138,"YYYY-MM") | W138: =IF(L138="","",IF(L138>pLateDays,1,0)) | X138: =IF(Q138>=pHighCutoff,1,0) | Y138: =IF(M138="Returned",1,0)
A139: HC-100137 | B139: 45540 | C139: West | D139: Store | E139: Kitchen | F139: Chef Knife | G139: Consumer | H139: 2 | I139: 68.79 | J139: 0.08 | K139: 24.76 | L139: 7 | M139: Completed | N139: S. Nguyen | O139: No | P139: =H139*I139 | Q139: =P139*(1-J139) | R139: =H139*K139 | S139: =IF(Q139=0,"",(Q139-R139)/Q139) | T139: =YEAR(B139) | U139: =YEAR(B139)&"-Q"&ROUNDUP(MONTH(B139)/3,0) | V139: =TEXT(B139,"YYYY-MM") | W139: =IF(L139="","",IF(L139>pLateDays,1,0)) | X139: =IF(Q139>=pHighCutoff,1,0) | Y139: =IF(M139="Returned",1,0)
A140: HC-100138 | B140: 45319 | C140: East | D140: Store | E140: Textiles | F140: Wool Throw | G140: Consumer | H140: 2 | I140: 66.04 | J140: 0.07 | K140: 27.74 | L140: 6 | M140: Completed | N140: P. Rossi | O140: No | P140: =H140*I140 | Q140: =P140*(1-J140) | R140: =H140*K140 | S140: =IF(Q140=0,"",(Q140-R140)/Q140) | T140: =YEAR(B140) | U140: =YEAR(B140)&"-Q"&ROUNDUP(MONTH(B140)/3,0) | V140: =TEXT(B140,"YYYY-MM") | W140: =IF(L140="","",IF(L140>pLateDays,1,0)) | X140: =IF(Q140>=pHighCutoff,1,0) | Y140: =IF(M140="Returned",1,0)
A141: HC-100139 | B141: 45838 | C141: South | D141: Store | E141: Furniture | F141: Oak Desk | G141: Consumer | H141: 3 | I141: 890.44 | J141: 0.11 | K141: 552.07 | L141: 7 | M141: Completed | N141: K. Mensah | O141: No | P141: =H141*I141 | Q141: =P141*(1-J141) | R141: =H141*K141 | S141: =IF(Q141=0,"",(Q141-R141)/Q141) | T141: =YEAR(B141) | U141: =YEAR(B141)&"-Q"&ROUNDUP(MONTH(B141)/3,0) | V141: =TEXT(B141,"YYYY-MM") | W141: =IF(L141="","",IF(L141>pLateDays,1,0)) | X141: =IF(Q141>=pHighCutoff,1,0) | Y141: =IF(M141="Returned",1,0)
A142: HC-100140 | B142: 45630 | C142: East | D142: Store | E142: Furniture | F142: Linen Sofa | G142: Home Office | H142: 2 | I142: 1119.44 | J142: 0.02 | K142: 738.83 | L142: 9 | M142: Completed | N142: S. Nguyen | O142: No | P142: =H142*I142 | Q142: =P142*(1-J142) | R142: =H142*K142 | S142: =IF(Q142=0,"",(Q142-R142)/Q142) | T142: =YEAR(B142) | U142: =YEAR(B142)&"-Q"&ROUNDUP(MONTH(B142)/3,0) | V142: =TEXT(B142,"YYYY-MM") | W142: =IF(L142="","",IF(L142>pLateDays,1,0)) | X142: =IF(Q142>=pHighCutoff,1,0) | Y142: =IF(M142="Returned",1,0)
A143: HC-100141 | B143: 45375 | C143: North | D143: Online | E143: Furniture | F143: Oak Desk | G143: Consumer | H143: 1 | I143: 883.26 | J143: 0.15 | K143: 547.62 | L143: 7 | M143: Completed | N143: S. Nguyen | O143: No | P143: =H143*I143 | Q143: =P143*(1-J143) | R143: =H143*K143 | S143: =IF(Q143=0,"",(Q143-R143)/Q143) | T143: =YEAR(B143) | U143: =YEAR(B143)&"-Q"&ROUNDUP(MONTH(B143)/3,0) | V143: =TEXT(B143,"YYYY-MM") | W143: =IF(L143="","",IF(L143>pLateDays,1,0)) | X143: =IF(Q143>=pHighCutoff,1,0) | Y143: =IF(M143="Returned",1,0)
A144: HC-100142 | B144: 45798 | C144: North | D144: Store | E144: Textiles | F144: Cotton Duvet | G144: Corporate | H144: 2 | I144: 125.03 | J144: 0.11 | K144: 55.01 | L144: 6 | M144: Completed | N144: L. Berger | O144: No | P144: =H144*I144 | Q144: =P144*(1-J144) | R144: =H144*K144 | S144: =IF(Q144=0,"",(Q144-R144)/Q144) | T144: =YEAR(B144) | U144: =YEAR(B144)&"-Q"&ROUNDUP(MONTH(B144)/3,0) | V144: =TEXT(B144,"YYYY-MM") | W144: =IF(L144="","",IF(L144>pLateDays,1,0)) | X144: =IF(Q144>=pHighCutoff,1,0) | Y144: =IF(M144="Returned",1,0)
A145: HC-100143 | B145: 45849 | C145: East | D145: Store | E145: Textiles | F145: Cotton Duvet | G145: Consumer | H145: 1 | I145: 103.34 | J145: 0.03 | K145: 45.47 | L145: 7 | M145: Cancelled | N145: J. Patel | O145: No | P145: =H145*I145 | Q145: =P145*(1-J145) | R145: =H145*K145 | S145: =IF(Q145=0,"",(Q145-R145)/Q145) | T145: =YEAR(B145) | U145: =YEAR(B145)&"-Q"&ROUNDUP(MONTH(B145)/3,0) | V145: =TEXT(B145,"YYYY-MM") | W145: =IF(L145="","",IF(L145>pLateDays,1,0)) | X145: =IF(Q145>=pHighCutoff,1,0) | Y145: =IF(M145="Returned",1,0)
A146: HC-100144 | B146: 45894 | C146: West | D146: Store | E146: Textiles | F146: Wool Throw | G146: Consumer | H146: 1 | I146: 74.95 | J146: 0.07 | K146: 31.48 | L146: 6 | M146: Completed | N146: K. Mensah | O146: No | P146: =H146*I146 | Q146: =P146*(1-J146) | R146: =H146*K146 | S146: =IF(Q146=0,"",(Q146-R146)/Q146) | T146: =YEAR(B146) | U146: =YEAR(B146)&"-Q"&ROUNDUP(MONTH(B146)/3,0) | V146: =TEXT(B146,"YYYY-MM") | W146: =IF(L146="","",IF(L146>pLateDays,1,0)) | X146: =IF(Q146>=pHighCutoff,1,0) | Y146: =IF(M146="Returned",1,0)
... A152: HC-100150 | B152: 45554 | C152: North | D152: Online | E152: Kitchen | F152: Cast Skillet | G152: Corporate | H152: 1 | I152: 51.18 | J152: 0.1 | K152: 20.47 | L152: 8 | M152: Completed | N152: M. Okonkwo | O152: No | P152: =H152*I152 | Q152: =P152*(1-J152) | R152: =H152*K152 | S152: =IF(Q152=0,"",(Q152-R152)/Q152) | T152: =YEAR(B152) | U152: =YEAR(B152)&"-Q"&ROUNDUP(MONTH(B152)/3,0) | V152: =TEXT(B152,"YYYY-MM") | W152: =IF(L152="","",IF(L152>pLateDays,1,0)) | X152: =IF(Q152>=pHighCutoff,1,0) | Y152: =IF(M152="Returned",1,0)
A153: HC-100151 | B153: 45870 | C153: West | D153: Wholesale | E153: Kitchen | F153: Cast Skillet | G153: Consumer | H153: 26 | I153: 53.28 | J153: 0.31 | K153: 21.31 | M153: Completed | N153: J. Patel | O153: No | P153: =H153*I153 | Q153: =P153*(1-J153) | R153: =H153*K153 | S153: =IF(Q153=0,"",(Q153-R153)/Q153) | T153: =YEAR(B153) | U153: =YEAR(B153)&"-Q"&ROUNDUP(MONTH(B153)/3,0) | V153: =TEXT(B153,"YYYY-MM") | W153: =IF(L153="","",IF(L153>pLateDays,1,0)) | X153: =IF(Q153>=pHighCutoff,1,0) | Y153: =IF(M153="Returned",1,0)
A154: HC-100152 | B154: 45507 | C154: North | D154: Online | E154: Textiles | F154: Wool Throw | G154: Corporate | H154: 3 | I154: 78.69 | J154: 0.04 | K154: 33.05 | L154: 6 | M154: Completed | N154: L. Berger | O154: No | P154: =H154*I154 | Q154: =P154*(1-J154) | R154: =H154*K154 | S154: =IF(Q154=0,"",(Q154-R154)/Q154) | T154: =YEAR(B154) | U154: =YEAR(B154)&"-Q"&ROUNDUP(MONTH(B154)/3,0) | V154: =TEXT(B154,"YYYY-MM") | W154: =IF(L154="","",IF(L154>pLateDays,1,0)) | X154: =IF(Q154>=pHighCutoff,1,0) | Y154: =IF(M154="Returned",1,0)
A155: HC-100153 | B155: 45868 | C155: West | D155: Store | E155: Furniture | F155: Walnut Shelf | G155: Unknown | H155: 4 | I155: 230.63 | J155: 0.04 | K155: 126.84 | L155: 7 | M155: Completed | N155: S. Nguyen | O155: No | P155: =H155*I155 | Q155: =P155*(1-J155) | R155: =H155*K155 | S155: =IF(Q155=0,"",(Q155-R155)/Q155) | T155: =YEAR(B155) | U155: =YEAR(B155)&"-Q"&ROUNDUP(MONTH(B155)/3,0) | V155: =TEXT(B155,"YYYY-MM") | W155: =IF(L155="","",IF(L155>pLateDays,1,0)) | X155: =IF(Q155>=pHighCutoff,1,0) | Y155: =IF(M155="Returned",1,0)
A156: HC-100154 | B156: 45356 | C156: North | D156: Online | E156: Furniture | F156: Walnut Shelf | G156: Home Office | H156: 1 | I156: 229.27 | J156: 0.05 | K156: 126.1 | L156: 5 | M156: Returned | N156: M. Okonkwo | O156: No | P156: =H156*I156 | Q156: =P156*(1-J156) | R156: =H156*K156 | S156: =IF(Q156=0,"",(Q156-R156)/Q156) | T156: =YEAR(B156) | U156: =YEAR(B156)&"-Q"&ROUNDUP(MONTH(B156)/3,0) | V156: =TEXT(B156,"YYYY-MM") | W156: =IF(L156="","",IF(L156>pLateDays,1,0)) | X156: =IF(Q156>=pHighCutoff,1,0) | Y156: =IF(M156="Returned",1,0)
A157: HC-100155 | B157: 45323 | C157: North | D157: Store | E157: Textiles | F157: Wool Throw | G157: Corporate | H157: 1 | I157: 70.08 | J157: 0.05 | K157: 29.43 | L157: 6 | M157: Completed | N157: P. Rossi | O157: No | P157: =H157*I157 | Q157: =P157*(1-J157) | R157: =H157*K157 | S157: =IF(Q157=0,"",(Q157-R157)/Q157) | T157: =YEAR(B157) | U157: =YEAR(B157)&"-Q"&ROUNDUP(MONTH(B157)/3,0) | V157: =TEXT(B157,"YYYY-MM") | W157: =IF(L157="","",IF(L157>pLateDays,1,0)) | X157: =IF(Q157>=pHighCutoff,1,0) | Y157: =IF(M157="Returned",1,0)
A158: HC-100156 | B158: 45500 | C158: West | D158: Store | E158: Furniture | F158: Lounge Chair | G158: Consumer | H158: 1 | I158: 447.1 | J158: 0.07 | K158: 268.26 | L158: 5 | M158: Returned | N158: A. Shah | O158: No | P158: =H158*I158 | Q158: =P158*(1-J158) | R158: =H158*K158 | S158: =IF(Q158=0,"",(Q158-R158)/Q158) | T158: =YEAR(B158) | U158: =YEAR(B158)&"-Q"&ROUNDUP(MONTH(B158)/3,0) | V158: =TEXT(B158,"YYYY-MM") | W158: =IF(L158="","",IF(L158>pLateDays,1,0)) | X158: =IF(Q158>=pHighCutoff,1,0) | Y158: =IF(M158="Returned",1,0)
A159: HC-100157 | B159: 45649 | C159: West | D159: Store | E159: Kitchen | F159: Cast Skillet | G159: Consumer | H159: 4 | I159: 57.84 | J159: 0.03 | K159: 23.13 | L159: 6 | M159: Completed | N159: R. Ibarra | O159: No | P159: =H159*I159 | Q159: =P159*(1-J159) | R159: =H159*K159 | S159: =IF(Q159=0,"",(Q159-R159)/Q159) | T159: =YEAR(B159) | U159: =YEAR(B159)&"-Q"&ROUNDUP(MONTH(B159)/3,0) | V159: =TEXT(B159,"YYYY-MM") | W159: =IF(L159="","",IF(L159>pLateDays,1,0)) | X159: =IF(Q159>=pHighCutoff,1,0) | Y159: =IF(M159="Returned",1,0)
A160: HC-100158 | B160: 45728 | C160: West | D160: Online | E160: Textiles | F160: Wool Throw | G160: Consumer | H160: 2 | I160: 70.39 | J160: 0.03 | K160: 29.57 | L160: 7 | M160: Completed | N160: L. Berger | O160: No | P160: =H160*I160 | Q160: =P160*(1-J160) | R160: =H160*K160 | S160: =IF(Q160=0,"",(Q160-R160)/Q160) | T160: =YEAR(B160) | U160: =YEAR(B160)&"-Q"&ROUNDUP(MONTH(B160)/3,0) | V160: =TEXT(B160,"YYYY-MM") | W160: =IF(L160="","",IF(L160>pLateDays,1,0)) | X160: =IF(Q160>=pHighCutoff,1,0) | Y160: =IF(M160="Returned",1,0)
A161: HC-100159 | B161: 45728 | C161: East | D161: Store | E161: Lighting | F161: Arc Lamp | G161: Consumer | H161: 4 | I161: 294.85 | J161: 0 | K161: 141.53 | L161: 8 | M161: Completed | N161: S. Nguyen | O161: No | P161: =H161*I161 | Q161: =P161*(1-J161) | R161: =H161*K161 | S161: =IF(Q161=0,"",(Q161-R161)/Q161) | T161: =YEAR(B161) | U161: =YEAR(B161)&"-Q"&ROUNDUP(MONTH(B161)/3,0) | V161: =TEXT(B161,"YYYY-MM") | W161: =IF(L161="","",IF(L161>pLateDays,1,0)) | X161: =IF(Q161>=pHighCutoff,1,0) | Y161: =IF(M161="Returned",1,0)
A162: HC-100160 | B162: 45870 | C162: South | D162: Store | E162: Furniture | F162: Linen Sofa | G162: Consumer | H162: 3 | I162: 1155.67 | J162: 0.12 | K162: 762.74 | L162: 8 | M162: Completed | N162: P. Rossi | O162: No | P162: =H162*I162 | Q162: =P162*(1-J162) | R162: =H162*K162 | S162: =IF(Q162=0,"",(Q162-R162)/Q162) | T162: =YEAR(B162) | U162: =YEAR(B162)&"-Q"&ROUNDUP(MONTH(B162)/3,0) | V162: =TEXT(B162,"YYYY-MM") | W162: =IF(L162="","",IF(L162>pLateDays,1,0)) | X162: =IF(Q162>=pHighCutoff,1,0) | Y162: =IF(M162="Returned",1,0)
A163: HC-100161 | B163: 45618 | C163: East | D163: Store | E163: Lighting | F163: Arc Lamp | G163: Consumer | H163: 4 | I163: 267.04 | J163: 0.04 | K163: 128.18 | L163: 8 | M163: Completed | N163: A. Shah | O163: No | P163: =H163*I163 | Q163: =P163*(1-J163) | R163: =H163*K163 | S163: =IF(Q163=0,"",(Q163-R163)/Q163) | T163: =YEAR(B163) | U163: =YEAR(B163)&"-Q"&ROUNDUP(MONTH(B163)/3,0) | V163: =TEXT(B163,"YYYY-MM") | W163: =IF(L163="","",IF(L163>pLateDays,1,0)) | X163: =IF(Q163>=pHighCutoff,1,0) | Y163: =IF(M163="Returned",1,0)
A164: HC-100162 | B164: 45830 | C164: East | D164: Wholesale | E164: Furniture | F164: Walnut Shelf | G164: Consumer | H164: 28 | I164: 192.58 | J164: 0.23 | K164: 105.92 | L164: 8 | M164: Completed | N164: A. Shah | O164: No | P164: =H164*I164 | Q164: =P164*(1-J164) | R164: =H164*K164 | S164: =IF(Q164=0,"",(Q164-R164)/Q164) | T164: =YEAR(B164) | U164: =YEAR(B164)&"-Q"&ROUNDUP(MONTH(B164)/3,0) | V164: =TEXT(B164,"YYYY-MM") | W164: =IF(L164="","",IF(L164>pLateDays,1,0)) | X164: =IF(Q164>=pHighCutoff,1,0) | Y164: =IF(M164="Returned",1,0)
...

Sheet Chart_Data
A1: Chart source — every number is a formula against CleanData and the dashboard parameters.
A3: Region | B3: NetRevenue | C3: Orders | D3: AvgMargin | E3: TotalCost
A4: North | B4: =SUMIFS(CleanData[NetRevenue],CleanData[OrderDate],">="&pStart,CleanData[OrderDate],"<="&pEnd,CleanData[Channel],IF(pChannel="All","<>",pChannel),CleanData[Category],IF(pCategory="All","<>",pCategory),CleanData[Status],IF(pIncludeCancelled="Yes","<>","<>Cancelled"),CleanData[Region],A4) | C4: =COUNTIFS(CleanData[OrderDate],">="&pStart,CleanData[OrderDate],"<="&pEnd,CleanData[Channel],IF(pChannel="All","<>",pChannel),CleanData[Category],IF(pCategory="All","<>",pCategory),CleanData[Status],IF(pIncludeCancelled="Yes","<>","<>Cancelled"),CleanData[Region],A4) | D4: =IFERROR(AVERAGEIFS(CleanData[Margin],CleanData[OrderDate],">="&pStart,CleanData[OrderDate],"<="&pEnd,CleanData[Channel],IF(pChannel="All","<>",pChannel),CleanData[Category],IF(pCategory="All","<>",pCategory),CleanData[Status],IF(pIncludeCancelled="Yes","<>","<>Cancelled"),CleanData[Region],A4),NA()) | E4: =SUMIFS(CleanData[TotalCost],CleanData[OrderDate],">="&pStart,CleanData[OrderDate],"<="&pEnd,CleanData[Channel],IF(pChannel="All","<>",pChannel),CleanData[Category],IF(pCategory="All","<>",pCategory),CleanData[Status],IF(pIncludeCancelled="Yes","<>","<>Cancelled"),CleanData[Region],A4)
A5: South | B5: =SUMIFS(CleanData[NetRevenue],CleanData[OrderDate],">="&pStart,CleanData[OrderDate],"<="&pEnd,CleanData[Channel],IF(pChannel="All","<>",pChannel),CleanData[Category],IF(pCategory="All","<>",pCategory),CleanData[Status],IF(pIncludeCancelled="Yes","<>","<>Cancelled"),CleanData[Region],A5) | C5: =COUNTIFS(CleanData[OrderDate],">="&pStart,CleanData[OrderDate],"<="&pEnd,CleanData[Channel],IF(pChannel="All","<>",pChannel),CleanData[Category],IF(pCategory="All","<>",pCategory),CleanData[Status],IF(pIncludeCancelled="Yes","<>","<>Cancelled"),CleanData[Region],A5) | D5: =IFERROR(AVERAGEIFS(CleanData[Margin],CleanData[OrderDate],">="&pStart,CleanData[OrderDate],"<="&pEnd,CleanData[Channel],IF(pChannel="All","<>",pChannel),CleanData[Category],IF(pCategory="All","<>",pCategory),CleanData[Status],IF(pIncludeCancelled="Yes","<>","<>Cancelled"),CleanData[Region],A5),NA()) | E5: =SUMIFS(CleanData[TotalCost],CleanData[OrderDate],">="&pStart,CleanData[OrderDate],"<="&pEnd,CleanData[Channel],IF(pChannel="All","<>",pChannel),CleanData[Category],IF(pCategory="All","<>",pCategory),CleanData[Status],IF(pIncludeCancelled="Yes","<>","<>Cancelled"),CleanData[Region],A5)
A6: East | B6: =SUMIFS(CleanData[NetRevenue],CleanData[OrderDate],">="&pStart,CleanData[OrderDate],"<="&pEnd,CleanData[Channel],IF(pChannel="All","<>",pChannel),CleanData[Category],IF(pCategory="All","<>",pCategory),CleanData[Status],IF(pIncludeCancelled="Yes","<>","<>Cancelled"),CleanData[Region],A6) | C6: =COUNTIFS(CleanData[OrderDate],">="&pStart,CleanData[OrderDate],"<="&pEnd,CleanData[Channel],IF(pChannel="All","<>",pChannel),CleanData[Category],IF(pCategory="All","<>",pCategory),CleanData[Status],IF(pIncludeCancelled="Yes","<>","<>Cancelled"),CleanData[Region],A6) | D6: =IFERROR(AVERAGEIFS(CleanData[Margin],CleanData[OrderDate],">="&pStart,CleanData[OrderDate],"<="&pEnd,CleanData[Channel],IF(pChannel="All","<>",pChannel),CleanData[Category],IF(pCategory="All","<>",pCategory),CleanData[Status],IF(pIncludeCancelled="Yes","<>","<>Cancelled"),CleanData[Region],A6),NA()) | E6: =SUMIFS(CleanData[TotalCost],CleanData[OrderDate],">="&pStart,CleanData[OrderDate],"<="&pEnd,CleanData[Channel],IF(pChannel="All","<>",pChannel),CleanData[Category],IF(pCategory="All","<>",pCategory),CleanData[Status],IF(pIncludeCancelled="Yes","<>","<>Cancelled"),CleanData[Region],A6)
A7: West | B7: =SUMIFS(CleanData[NetRevenue],CleanData[OrderDate],">="&pStart,CleanData[OrderDate],"<="&pEnd,CleanData[Channel],IF(pChannel="All","<>",pChannel),CleanData[Category],IF(pCategory="All","<>",pCategory),CleanData[Status],IF(pIncludeCancelled="Yes","<>","<>Cancelled"),CleanData[Region],A7) | C7: =COUNTIFS(CleanData[OrderDate],">="&pStart,CleanData[OrderDate],"<="&pEnd,CleanData[Channel],IF(pChannel="All","<>",pChannel),CleanData[Category],IF(pCategory="All","<>",pCategory),CleanData[Status],IF(pIncludeCancelled="Yes","<>","<>Cancelled"),CleanData[Region],A7) | D7: =IFERROR(AVERAGEIFS(CleanData[Margin],CleanData[OrderDate],">="&pStart,CleanData[OrderDate],"<="&pEnd,CleanData[Channel],IF(pChannel="All","<>",pChannel),CleanData[Category],IF(pCategory="All","<>",pCategory),CleanData[Status],IF(pIncludeCancelled="Yes","<>","<>Cancelled"),CleanData[Region],A7),NA()) | E7: =SUMIFS(CleanData[TotalCost],CleanData[OrderDate],">="&pStart,CleanData[OrderDate],"<="&pEnd,CleanData[Channel],IF(pChannel="All","<>",pChannel),CleanData[Category],IF(pCategory="All","<>",pCategory),CleanData[Status],IF(pIncludeCancelled="Yes","<>","<>Cancelled"),CleanData[Region],A7)
A9: Channel | B9: Orders | C9: NetRevenue
A10: Store | B10: =COUNTIFS(CleanData[OrderDate],">="&pStart,CleanData[OrderDate],"<="&pEnd,CleanData[Region],IF(pRegion="All","<>",pRegion),CleanData[Category],IF(pCategory="All","<>",pCategory),CleanData[Status],IF(pIncludeCancelled="Yes","<>","<>Cancelled"),CleanData[Channel],A10) | C10: =SUMIFS(CleanData[NetRevenue],CleanData[OrderDate],">="&pStart,CleanData[OrderDate],"<="&pEnd,CleanData[Region],IF(pRegion="All","<>",pRegion),CleanData[Category],IF(pCategory="All","<>",pCategory),CleanData[Status],IF(pIncludeCancelled="Yes","<>","<>Cancelled"),CleanData[Channel],A10)
A11: Online | B11: =COUNTIFS(CleanData[OrderDate],">="&pStart,CleanData[OrderDate],"<="&pEnd,CleanData[Region],IF(pRegion="All","<>",pRegion),CleanData[Category],IF(pCategory="All","<>",pCategory),CleanData[Status],IF(pIncludeCancelled="Yes","<>","<>Cancelled"),CleanData[Channel],A11) | C11: =SUMIFS(CleanData[NetRevenue],CleanData[OrderDate],">="&pStart,CleanData[OrderDate],"<="&pEnd,CleanData[Region],IF(pRegion="All","<>",pRegion),CleanData[Category],IF(pCategory="All","<>",pCategory),CleanData[Status],IF(pIncludeCancelled="Yes","<>","<>Cancelled"),CleanData[Channel],A11)
A12: Wholesale | B12: =COUNTIFS(CleanData[OrderDate],">="&pStart,CleanData[OrderDate],"<="&pEnd,CleanData[Region],IF(pRegion="All","<>",pRegion),CleanData[Category],IF(pCategory="All","<>",pCategory),CleanData[Status],IF(pIncludeCancelled="Yes","<>","<>Cancelled"),CleanData[Channel],A12) | C12: =SUMIFS(CleanData[NetRevenue],CleanData[OrderDate],">="&pStart,CleanData[OrderDate],"<="&pEnd,CleanData[Region],IF(pRegion="All","<>",pRegion),CleanData[Category],IF(pCategory="All","<>",pCategory),CleanData[Status],IF(pIncludeCancelled="Yes","<>","<>Cancelled"),CleanData[Channel],A12)
A14: YearMonth | B14: NetRevenue | C14: Orders
A15: 2024-01 | B15: =SUMIFS(CleanData[NetRevenue],CleanData[OrderDate],">="&pStart,CleanData[OrderDate],"<="&pEnd,CleanData[Region],IF(pRegion="All","<>",pRegion),CleanData[Channel],IF(pChannel="All","<>",pChannel),CleanData[Category],IF(pCategory="All","<>",pCategory),CleanData[Status],IF(pIncludeCancelled="Yes","<>","<>Cancelled"),CleanData[YearMonth],A15) | C15: =COUNTIFS(CleanData[OrderDate],">="&pStart,CleanData[OrderDate],"<="&pEnd,CleanData[Region],IF(pRegion="All","<>",pRegion),CleanData[Channel],IF(pChannel="All","<>",pChannel),CleanData[Category],IF(pCategory="All","<>",pCategory),CleanData[Status],IF(pIncludeCancelled="Yes","<>","<>Cancelled"),CleanData[YearMonth],A15)
A16: 2024-02 | B16: =SUMIFS(CleanData[NetRevenue],CleanData[OrderDate],">="&pStart,CleanData[OrderDate],"<="&pEnd,CleanData[Region],IF(pRegion="All","<>",pRegion),CleanData[Channel],IF(pChannel="All","<>",pChannel),CleanData[Category],IF(pCategory="All","<>",pCategory),CleanData[Status],IF(pIncludeCancelled="Yes","<>","<>Cancelled"),CleanData[YearMonth],A16) | C16: =COUNTIFS(CleanData[OrderDate],">="&pStart,CleanData[OrderDate],"<="&pEnd,CleanData[Region],IF(pRegion="All","<>",pRegion),CleanData[Channel],IF(pChannel="All","<>",pChannel),CleanData[Category],IF(pCategory="All","<>",pCategory),CleanData[Status],IF(pIncludeCancelled="Yes","<>","<>Cancelled"),CleanData[YearMonth],A16)
A17: 2024-03 | B17: =SUMIFS(CleanData[NetRevenue],CleanData[OrderDate],">="&pStart,CleanData[OrderDate],"<="&pEnd,CleanData[Region],IF(pRegion="All","<>",pRegion),CleanData[Channel],IF(pChannel="All","<>",pChannel),CleanData[Category],IF(pCategory="All","<>",pCategory),CleanData[Status],IF(pIncludeCancelled="Yes","<>","<>Cancelled"),CleanData[YearMonth],A17) | C17: =COUNTIFS(CleanData[OrderDate],">="&pStart,CleanData[OrderDate],"<="&pEnd,CleanData[Region],IF(pRegion="All","<>",pRegion),CleanData[Channel],IF(pChannel="All","<>",pChannel),CleanData[Category],IF(pCategory="All","<>",pCategory),CleanData[Status],IF(pIncludeCancelled="Yes","<>","<>Cancelled"),CleanData[YearMonth],A17)
A18: 2024-04 | B18: =SUMIFS(CleanData[NetRevenue],CleanData[OrderDate],">="&pStart,CleanData[OrderDate],"<="&pEnd,CleanData[Region],IF(pRegion="All","<>",pRegion),CleanData[Channel],IF(pChannel="All","<>",pChannel),CleanData[Category],IF(pCategory="All","<>",pCategory),CleanData[Status],IF(pIncludeCancelled="Yes","<>","<>Cancelled"),CleanData[YearMonth],A18) | C18: =COUNTIFS(CleanData[OrderDate],">="&pStart,CleanData[OrderDate],"<="&pEnd,CleanData[Region],IF(pRegion="All","<>",pRegion),CleanData[Channel],IF(pChannel="All","<>",pChannel),CleanData[Category],IF(pCategory="All","<>",pCategory),CleanData[Status],IF(pIncludeCancelled="Yes","<>","<>Cancelled"),CleanData[YearMonth],A18)
A19: 2024-05 | B19: =SUMIFS(CleanData[NetRevenue],CleanData[OrderDate],">="&pStart,CleanData[OrderDate],"<="&pEnd,CleanData[Region],IF(pRegion="All","<>",pRegion),CleanData[Channel],IF(pChannel="All","<>",pChannel),CleanData[Category],IF(pCategory="All","<>",pCategory),CleanData[Status],IF(pIncludeCancelled="Yes","<>","<>Cancelled"),CleanData[YearMonth],A19) | C19: =COUNTIFS(CleanData[OrderDate],">="&pStart,CleanData[OrderDate],"<="&pEnd,CleanData[Region],IF(pRegion="All","<>",pRegion),CleanData[Channel],IF(pChannel="All","<>",pChannel),CleanData[Category],IF(pCategory="All","<>",pCategory),CleanData[Status],IF(pIncludeCancelled="Yes","<>","<>Cancelled"),CleanData[YearMonth],A19)
A20: 2024-06 | B20: =SUMIFS(CleanData[NetRevenue],CleanData[OrderDate],">="&pStart,CleanData[OrderDate],"<="&pEnd,CleanData[Region],IF(pRegion="All","<>",pRegion),CleanData[Channel],IF(pChannel="All","<>",pChannel),CleanData[Category],IF(pCategory="All","<>",pCategory),CleanData[Status],IF(pIncludeCancelled="Yes","<>","<>Cancelled"),CleanData[YearMonth],A20) | C20: =COUNTIFS(CleanData[OrderDate],">="&pStart,CleanData[OrderDate],"<="&pEnd,CleanData[Region],IF(pRegion="All","<>",pRegion),CleanData[Channel],IF(pChannel="All","<>",pChannel),CleanData[Category],IF(pCategory="All","<>",pCategory),CleanData[Status],IF(pIncludeCancelled="Yes","<>","<>Cancelled"),CleanData[YearMonth],A20)
A21: 2024-07 | B21: =SUMIFS(CleanData[NetRevenue],CleanData[OrderDate],">="&pStart,CleanData[OrderDate],"<="&pEnd,CleanData[Region],IF(pRegion="All","<>",pRegion),CleanData[Channel],IF(pChannel="All","<>",pChannel),CleanData[Category],IF(pCategory="All","<>",pCategory),CleanData[Status],IF(pIncludeCancelled="Yes","<>","<>Cancelled"),CleanData[YearMonth],A21) | C21: =COUNTIFS(CleanData[OrderDate],">="&pStart,CleanData[OrderDate],"<="&pEnd,CleanData[Region],IF(pRegion="All","<>",pRegion),CleanData[Channel],IF(pChannel="All","<>",pChannel),CleanData[Category],IF(pCategory="All","<>",pCategory),CleanData[Status],IF(pIncludeCancelled="Yes","<>","<>Cancelled"),CleanData[YearMonth],A21)
A22: 2024-08 | B22: =SUMIFS(CleanData[NetRevenue],CleanData[OrderDate],">="&pStart,CleanData[OrderDate],"<="&pEnd,CleanData[Region],IF(pRegion="All","<>",pRegion),CleanData[Channel],IF(pChannel="All","<>",pChannel),CleanData[Category],IF(pCategory="All","<>",pCategory),CleanData[Status],IF(pIncludeCancelled="Yes","<>","<>Cancelled"),CleanData[YearMonth],A22) | C22: =COUNTIFS(CleanData[OrderDate],">="&pStart,CleanData[OrderDate],"<="&pEnd,CleanData[Region],IF(pRegion="All","<>",pRegion),CleanData[Channel],IF(pChannel="All","<>",pChannel),CleanData[Category],IF(pCategory="All","<>",pCategory),CleanData[Status],IF(pIncludeCancelled="Yes","<>","<>Cancelled"),CleanData[YearMonth],A22)
A23: 2024-09 | B23: =SUMIFS(CleanData[NetRevenue],CleanData[OrderDate],">="&pStart,CleanData[OrderDate],"<="&pEnd,CleanData[Region],IF(pRegion="All","<>",pRegion),CleanData[Channel],IF(pChannel="All","<>",pChannel),CleanData[Category],IF(pCategory="All","<>",pCategory),CleanData[Status],IF(pIncludeCancelled="Yes","<>","<>Cancelled"),CleanData[YearMonth],A23) | C23: =COUNTIFS(CleanData[OrderDate],">="&pStart,CleanData[OrderDate],"<="&pEnd,CleanData[Region],IF(pRegion="All","<>",pRegion),CleanData[Channel],IF(pChannel="All","<>",pChannel),CleanData[Category],IF(pCategory="All","<>",pCategory),CleanData[Status],IF(pIncludeCancelled="Yes","<>","<>Cancelled"),CleanData[YearMonth],A23)
A24: 2024-10 | B24: =SUMIFS(CleanData[NetRevenue],CleanData[OrderDate],">="&pStart,CleanData[OrderDate],"<="&pEnd,CleanData[Region],IF(pRegion="All","<>",pRegion),CleanData[Channel],IF(pChannel="All","<>",pChannel),CleanData[Category],IF(pCategory="All","<>",pCategory),CleanData[Status],IF(pIncludeCancelled="Yes","<>","<>Cancelled"),CleanData[YearMonth],A24) | C24: =COUNTIFS(CleanData[OrderDate],">="&pStart,CleanData[OrderDate],"<="&pEnd,CleanData[Region],IF(pRegion="All","<>",pRegion),CleanData[Channel],IF(pChannel="All","<>",pChannel),CleanData[Category],IF(pCategory="All","<>",pCategory),CleanData[Status],IF(pIncludeCancelled="Yes","<>","<>Cancelled"),CleanData[YearMonth],A24)
A25: 2024-11 | B25: =SUMIFS(CleanData[NetRevenue],CleanData[OrderDate],">="&pStart,CleanData[OrderDate],"<="&pEnd,CleanData[Region],IF(pRegion="All","<>",pRegion),CleanData[Channel],IF(pChannel="All","<>",pChannel),CleanData[Category],IF(pCategory="All","<>",pCategory),CleanData[Status],IF(pIncludeCancelled="Yes","<>","<>Cancelled"),CleanData[YearMonth],A25) | C25: =COUNTIFS(CleanData[OrderDate],">="&pStart,CleanData[OrderDate],"<="&pEnd,CleanData[Region],IF(pRegion="All","<>",pRegion),CleanData[Channel],IF(pChannel="All","<>",pChannel),CleanData[Category],IF(pCategory="All","<>",pCategory),CleanData[Status],IF(pIncludeCancelled="Yes","<>","<>Cancelled"),CleanData[YearMonth],A25)
A26: 2024-12 | B26: =SUMIFS(CleanData[NetRevenue],CleanData[OrderDate],">="&pStart,CleanData[OrderDate],"<="&pEnd,CleanData[Region],IF(pRegion="All","<>",pRegion),CleanData[Channel],IF(pChannel="All","<>",pChannel),CleanData[Category],IF(pCategory="All","<>",pCategory),CleanData[Status],IF(pIncludeCancelled="Yes","<>","<>Cancelled"),CleanData[YearMonth],A26) | C26: =COUNTIFS(CleanData[OrderDate],">="&pStart,CleanData[OrderDate],"<="&pEnd,CleanData[Region],IF(pRegion="All","<>",pRegion),CleanData[Channel],IF(pChannel="All","<>",pChannel),CleanData[Category],IF(pCategory="All","<>",pCategory),CleanData[Status],IF(pIncludeCancelled="Yes","<>","<>Cancelled"),CleanData[YearMonth],A26)
... A35: 2025-09 | B35: =SUMIFS(CleanData[NetRevenue],CleanData[OrderDate],">="&pStart,CleanData[OrderDate],"<="&pEnd,CleanData[Region],IF(pRegion="All","<>",pRegion),CleanData[Channel],IF(pChannel="All","<>",pChannel),CleanData[Category],IF(pCategory="All","<>",pCategory),CleanData[Status],IF(pIncludeCancelled="Yes","<>","<>Cancelled"),CleanData[YearMonth],A35) | C35: =COUNTIFS(CleanData[OrderDate],">="&pStart,CleanData[OrderDate],"<="&pEnd,CleanData[Region],IF(pRegion="All","<>",pRegion),CleanData[Channel],IF(pChannel="All","<>",pChannel),CleanData[Category],IF(pCategory="All","<>",pCategory),CleanData[Status],IF(pIncludeCancelled="Yes","<>","<>Cancelled"),CleanData[YearMonth],A35)
A37: Category | B37: North | C37: South | D37: East | E37: West
A38: Furniture | B38: =SUMIFS(CleanData[NetRevenue],CleanData[OrderDate],">="&pStart,CleanData[OrderDate],"<="&pEnd,CleanData[Channel],IF(pChannel="All","<>",pChannel),CleanData[Status],IF(pIncludeCancelled="Yes","<>","<>Cancelled"),CleanData[Category],A38,CleanData[Region],B$37) | C38: =SUMIFS(CleanData[NetRevenue],CleanData[OrderDate],">="&pStart,CleanData[OrderDate],"<="&pEnd,CleanData[Channel],IF(pChannel="All","<>",pChannel),CleanData[Status],IF(pIncludeCancelled="Yes","<>","<>Cancelled"),CleanData[Category],A38,CleanData[Region],C$37) | D38: =SUMIFS(CleanData[NetRevenue],CleanData[OrderDate],">="&pStart,CleanData[OrderDate],"<="&pEnd,CleanData[Channel],IF(pChannel="All","<>",pChannel),CleanData[Status],IF(pIncludeCancelled="Yes","<>","<>Cancelled"),CleanData[Category],A38,CleanData[Region],D$37) | E38: =SUMIFS(CleanData[NetRevenue],CleanData[OrderDate],">="&pStart,CleanData[OrderDate],"<="&pEnd,CleanData[Channel],IF(pChannel="All","<>",pChannel),CleanData[Status],IF(pIncludeCancelled="Yes","<>","<>Cancelled"),CleanData[Category],A38,CleanData[Region],E$37)
A39: Lighting | B39: =SUMIFS(CleanData[NetRevenue],CleanData[OrderDate],">="&pStart,CleanData[OrderDate],"<="&pEnd,CleanData[Channel],IF(pChannel="All","<>",pChannel),CleanData[Status],IF(pIncludeCancelled="Yes","<>","<>Cancelled"),CleanData[Category],A39,CleanData[Region],B$37) | C39: =SUMIFS(CleanData[NetRevenue],CleanData[OrderDate],">="&pStart,CleanData[OrderDate],"<="&pEnd,CleanData[Channel],IF(pChannel="All","<>",pChannel),CleanData[Status],IF(pIncludeCancelled="Yes","<>","<>Cancelled"),CleanData[Category],A39,CleanData[Region],C$37) | D39: =SUMIFS(CleanData[NetRevenue],CleanData[OrderDate],">="&pStart,CleanData[OrderDate],"<="&pEnd,CleanData[Channel],IF(pChannel="All","<>",pChannel),CleanData[Status],IF(pIncludeCancelled="Yes","<>","<>Cancelled"),CleanData[Category],A39,CleanData[Region],D$37) | E39: =SUMIFS(CleanData[NetRevenue],CleanData[OrderDate],">="&pStart,CleanData[OrderDate],"<="&pEnd,CleanData[Channel],IF(pChannel="All","<>",pChannel),CleanData[Status],IF(pIncludeCancelled="Yes","<>","<>Cancelled"),CleanData[Category],A39,CleanData[Region],E$37)
A40: Textiles | B40: =SUMIFS(CleanData[NetRevenue],CleanData[OrderDate],">="&pStart,CleanData[OrderDate],"<="&pEnd,CleanData[Channel],IF(pChannel="All","<>",pChannel),CleanData[Status],IF(pIncludeCancelled="Yes","<>","<>Cancelled"),CleanData[Category],A40,CleanData[Region],B$37) | C40: =SUMIFS(CleanData[NetRevenue],CleanData[OrderDate],">="&pStart,CleanData[OrderDate],"<="&pEnd,CleanData[Channel],IF(pChannel="All","<>",pChannel),CleanData[Status],IF(pIncludeCancelled="Yes","<>","<>Cancelled"),CleanData[Category],A40,CleanData[Region],C$37) | D40: =SUMIFS(CleanData[NetRevenue],CleanData[OrderDate],">="&pStart,CleanData[OrderDate],"<="&pEnd,CleanData[Channel],IF(pChannel="All","<>",pChannel),CleanData[Status],IF(pIncludeCancelled="Yes","<>","<>Cancelled"),CleanData[Category],A40,CleanData[Region],D$37) | E40: =SUMIFS(CleanData[NetRevenue],CleanData[OrderDate],">="&pStart,CleanData[OrderDate],"<="&pEnd,CleanData[Channel],IF(pChannel="All","<>",pChannel),CleanData[Status],IF(pIncludeCancelled="Yes","<>","<>Cancelled"),CleanData[Category],A40,CleanData[Region],E$37)
A41: Kitchen | B41: =SUMIFS(CleanData[NetRevenue],CleanData[OrderDate],">="&pStart,CleanData[OrderDate],"<="&pEnd,CleanData[Channel],IF(pChannel="All","<>",pChannel),CleanData[Status],IF(pIncludeCancelled="Yes","<>","<>Cancelled"),CleanData[Category],A41,CleanData[Region],B$37) | C41: =SUMIFS(CleanData[NetRevenue],CleanData[OrderDate],">="&pStart,CleanData[OrderDate],"<="&pEnd,CleanData[Channel],IF(pChannel="All","<>",pChannel),CleanData[Status],IF(pIncludeCancelled="Yes","<>","<>Cancelled"),CleanData[Category],A41,CleanData[Region],C$37) | D41: =SUMIFS(CleanData[NetRevenue],CleanData[OrderDate],">="&pStart,CleanData[OrderDate],"<="&pEnd,CleanData[Channel],IF(pChannel="All","<>",pChannel),CleanData[Status],IF(pIncludeCancelled="Yes","<>","<>Cancelled"),CleanData[Category],A41,CleanData[Region],D$37) | E41: =SUMIFS(CleanData[NetRevenue],CleanData[OrderDate],">="&pStart,CleanData[OrderDate],"<="&pEnd,CleanData[Channel],IF(pChannel="All","<>",pChannel),CleanData[Status],IF(pIncludeCancelled="Yes","<>","<>Cancelled"),CleanData[Category],A41,CleanData[Region],E$37)
A43: Quarter | B43: NetRevenue
A44: 2024-Q1 | B44: =SUMIFS(CleanData[NetRevenue],CleanData[OrderDate],">="&pStart,CleanData[OrderDate],"<="&pEnd,CleanData[Region],IF(pRegion="All","<>",pRegion),CleanData[Channel],IF(pChannel="All","<>",pChannel),CleanData[Category],IF(pCategory="All","<>",pCategory),CleanData[Status],IF(pIncludeCancelled="Yes","<>","<>Cancelled"),CleanData[Quarter],A44)
A45: 2024-Q2 | B45: =SUMIFS(CleanData[NetRevenue],CleanData[OrderDate],">="&pStart,CleanData[OrderDate],"<="&pEnd,CleanData[Region],IF(pRegion="All","<>",pRegion),CleanData[Channel],IF(pChannel="All","<>",pChannel),CleanData[Category],IF(pCategory="All","<>",pCategory),CleanData[Status],IF(pIncludeCancelled="Yes","<>","<>Cancelled"),CleanData[Quarter],A45)
A46: 2024-Q3 | B46: =SUMIFS(CleanData[NetRevenue],CleanData[OrderDate],">="&pStart,CleanData[OrderDate],"<="&pEnd,CleanData[Region],IF(pRegion="All","<>",pRegion),CleanData[Channel],IF(pChannel="All","<>",pChannel),CleanData[Category],IF(pCategory="All","<>",pCategory),CleanData[Status],IF(pIncludeCancelled="Yes","<>","<>Cancelled"),CleanData[Quarter],A46)
A47: 2024-Q4 | B47: =SUMIFS(CleanData[NetRevenue],CleanData[OrderDate],">="&pStart,CleanData[OrderDate],"<="&pEnd,CleanData[Region],IF(pRegion="All","<>",pRegion),CleanData[Channel],IF(pChannel="All","<>",pChannel),CleanData[Category],IF(pCategory="All","<>",pCategory),CleanData[Status],IF(pIncludeCancelled="Yes","<>","<>Cancelled"),CleanData[Quarter],A47)
A48: 2025-Q1 | B48: =SUMIFS(CleanData[NetRevenue],CleanData[OrderDate],">="&pStart,CleanData[OrderDate],"<="&pEnd,CleanData[Region],IF(pRegion="All","<>",pRegion),CleanData[Channel],IF(pChannel="All","<>",pChannel),CleanData[Category],IF(pCategory="All","<>",pCategory),CleanData[Status],IF(pIncludeCancelled="Yes","<>","<>Cancelled"),CleanData[Quarter],A48)
A49: 2025-Q2 | B49: =SUMIFS(CleanData[NetRevenue],CleanData[OrderDate],">="&pStart,CleanData[OrderDate],"<="&pEnd,CleanData[Region],IF(pRegion="All","<>",pRegion),CleanData[Channel],IF(pChannel="All","<>",pChannel),CleanData[Category],IF(pCategory="All","<>",pCategory),CleanData[Status],IF(pIncludeCancelled="Yes","<>","<>Cancelled"),CleanData[Quarter],A49)
A50: 2025-Q3 | B50: =SUMIFS(CleanData[NetRevenue],CleanData[OrderDate],">="&pStart,CleanData[OrderDate],"<="&pEnd,CleanData[Region],IF(pRegion="All","<>",pRegion),CleanData[Channel],IF(pChannel="All","<>",pChannel),CleanData[Category],IF(pCategory="All","<>",pCategory),CleanData[Status],IF(pIncludeCancelled="Yes","<>","<>Cancelled"),CleanData[Quarter],A50)
A52: Status | B52: Orders
A53: Completed | B53: =COUNTIFS(CleanData[OrderDate],">="&pStart,CleanData[OrderDate],"<="&pEnd,CleanData[Region],IF(pRegion="All","<>",pRegion),CleanData[Channel],IF(pChannel="All","<>",pChannel),CleanData[Category],IF(pCategory="All","<>",pCategory),CleanData[Status],A53)
A54: Returned | B54: =COUNTIFS(CleanData[OrderDate],">="&pStart,CleanData[OrderDate],"<="&pEnd,CleanData[Region],IF(pRegion="All","<>",pRegion),CleanData[Channel],IF(pChannel="All","<>",pChannel),CleanData[Category],IF(pCategory="All","<>",pCategory),CleanData[Status],A54)
...

Sheet Analysis
A1: Analysis
A2: Live SUMIFS summaries follow the dashboard filters. The top-10 list is a snapshot from the last pipeline run at All / All / All.
B5: =Chart_Data!A4 | C5: =Chart_Data!B4 | D5: =Chart_Data!C4 | E5: =IF(D5=0,NA(),C5/D5) | F5: =IF(C5=0,NA(),(C5-Chart_Data!E4)/C5) | G5: =Chart_Data!D4
B6: =Chart_Data!A5 | C6: =Chart_Data!B5 | D6: =Chart_Data!C5 | E6: =IF(D6=0,NA(),C6/D6) | F6: =IF(C6=0,NA(),(C6-Chart_Data!E5)/C6) | G6: =Chart_Data!D5
B7: =Chart_Data!A6 | C7: =Chart_Data!B6 | D7: =Chart_Data!C6 | E7: =IF(D7=0,NA(),C7/D7) | F7: =IF(C7=0,NA(),(C7-Chart_Data!E6)/C7) | G7: =Chart_Data!D6
B8: =Chart_Data!A7 | C8: =Chart_Data!B7 | D8: =Chart_Data!C7 | E8: =IF(D8=0,NA(),C8/D8) | F8: =IF(C8=0,NA(),(C8-Chart_Data!E7)/C8) | G8: =Chart_Data!D7
B11: Top 10 orders by net revenue (pipeline snapshot, default filters)
B13: HC-100483 | C13: 45785 | D13: West | E13: Furniture | F13: Linen Sofa | G13: Completed | H13: 29393.95 | I13: 0.19512416
B14: HC-100098 | C14: 45834 | D14: South | E14: Furniture | F14: Linen Sofa | G14: Completed | H14: 28854.411 | I14: 0.24138324
B15: HC-101367 | C15: 45656 | D15: East | E15: Furniture | F15: Linen Sofa | G15: Completed | H15: 27550.785 | I15: 0.1199964
B16: HC-101139 | C16: 45875 | D16: East | E16: Furniture | F16: Linen Sofa | G16: Completed | H16: 26399.976 | I16: 0.20481708
B17: HC-100766 | C17: 45835 | D17: West | E17: Furniture | F17: Linen Sofa | G17: Completed | H17: 25359.09 | I17: 0.20481846
B18: HC-101257 | C18: 45801 | D18: West | E18: Furniture | F18: Linen Sofa | G18: Completed | H18: 24770.535 | I18: 0.19511954
B19: HC-100479 | C19: 45849 | D19: West | E19: Furniture | F19: Linen Sofa | G19: Completed | H19: 23947.739 | I19: 0.1951282
B20: HC-100845 | C20: 45374 | D20: South | E20: Furniture | F20: Linen Sofa | G20: Completed | H20: 23405.242 | I20: 0.043480927
B21: HC-101568 | C21: 45703 | D21: North | E21: Furniture | F21: Linen Sofa | G21: Completed | H21: 23215.853 | I21: 0.029413212
B22: HC-100799 | C22: 45806 | D22: West | E22: Furniture | F22: Oak Desk | G22: Completed | H22: 23155.318 | I22: 0.27059519
B24: Weighted margin is (net revenue - cost) / net revenue. Unweighted margin is the average of order-level margins. A region can look healthier on one definition than the other when a few large wholesale tickets dominate.

Sheet Dashboard
A1: Harbor & Co. · Sales performance
A2: Excel pipeline dashboard. Change the controls, then let Excel calculate. Comparison charts ignore the filter that would collapse them.
C5: All | E5: All | G5: All | I5: No | K5: 45292 | M5: 45930
A6: Shipment lateness and the low-margin floor live on Parameters. The high-value cutoff is calculated for this saved window; rerun the pipeline after changing dates if you need a new percentile.
A8: Net revenue | C8: Orders | E8: Average order value | G8: Gross margin | I8: Return rate | K8: On-time fulfillment | M8: High-value orders | O8: Low-margin orders
